<?xml version="1.0" encoding="utf-8"?>
<!-- This URDF was automatically created by SolidWorks to URDF Exporter! Originally created by Stephen Brawner (brawner@gmail.com) 
     Commit Version: 1.6.0-4-g7f85cfe  Build Version: 1.6.7995.38578
     For more information, please see http://wiki.ros.org/sw_urdf_exporter -->
<robot
  name="robotic_arm">
  
  <link
    name="base_link">
    <inertial>
      <origin
        xyz="0.001243 9.6973E-06 0.018348"
        rpy="0 0 0" />
      <mass
        value="0.14032" />
      <inertia
        ixx="224200000"
        ixy="-102530000"
        ixz="10964000"
        iyy="935460000"
        iyz="-533770"
        izz="777040000" />
    </inertial>
    <visual>
      <origin
        xyz="0 0 0"
        rpy="0 0 0" />
      <geometry>
        <mesh
          filename="package://robotic_arm/meshes/base_link.STL" />
      </geometry>
      <material
        name="">
        <color
          rgba="0.69804 0.69804 0.69804 1" />
      </material>
    </visual>
    <collision>
      <origin
        xyz="0 0 0"
        rpy="0 0 0" />
      <geometry>
        <mesh
          filename="package://robotic_arm/meshes/base_link.STL" />
      </geometry>
    </collision>
  </link>
  
  <link
    name="link_1">
    <inertial>
      <origin
        xyz="0.012 -0.00063149 0.0083979"
        rpy="0 0 0" />
      <mass
        value="0.05168" />
      <inertia
        ixx="26860"
        ixy="525.09"
        ixz="287.62"
        iyy="16993"
        iyz="-523.85"
        izz="26995" />
    </inertial>
    <visual>
      <origin
        xyz="0 0 0"
        rpy="0 0 0" />
      <geometry>
        <mesh
          filename="package://robotic_arm/meshes/link_1.STL" />
      </geometry>
      <material
        name="">
        <color
          rgba="0.79216 0.81961 0.93333 1" />
      </material>
    </visual>
    <collision>
      <origin
        xyz="0 0 0"
        rpy="0 0 0" />
      <geometry>
        <mesh
          filename="package://robotic_arm/meshes/link_1.STL" />
      </geometry>
    </collision>
  </link>
  
  <joint
    name="joint_1"
    type="continuous">
    <origin
      xyz="0 0 0.039971"
      rpy="0 0 0" />
    <parent
      link="base_link" />
    <child
      link="link_1" />
    <axis
      xyz="0 0 1" />
    <limit
      lower="0"
      upper="0"
      effort="0"
      velocity="0" />
  </joint>
  <link
    name="link_2">
    <inertial>
      <origin
        xyz="-0.011752 -0.099865 -0.019"
        rpy="0 0 0" />
      <mass
        value="0.10228" />
      <inertia
        ixx="512810000"
        ixy="108850000"
        ixz="380"
        iyy="56237000"
        iyz="2370"
        izz="523870000" />
    </inertial>
    <visual>
      <origin
        xyz="0 0 0"
        rpy="0 0 0" />
      <geometry>
        <mesh
          filename="package://robotic_arm/meshes/link_2.STL" />
      </geometry>
      <material
        name="">
        <color
          rgba="0.69804 0.69804 0.69804 1" />
      </material>
    </visual>
    <collision>
      <origin
        xyz="0 0 0"
        rpy="0 0 0" />
      <geometry>
        <mesh
          filename="package://robotic_arm/meshes/link_2.STL" />
      </geometry>
    </collision>
  </link>
  <joint
    name="joint_2"
    type="continuous">
    <origin
      xyz="0.024 0.019 0.0090292"
      rpy="-1.5708 -0.0070881 0" />
    <parent
      link="link_1" />
    <child
      link="link_2" />
    <axis
      xyz="0 0 1" />
    <limit
      lower="0"
      upper="0"
      effort="0"
      velocity="0" />
  </joint>
  <link
    name="link_3">
    <inertial>
      <origin
        xyz="0.00063139 0.012 -0.00063149"
        rpy="0 0 0" />
      <mass
        value="0.05168" />
      <inertia
        ixx="26860"
        ixy="525.09"
        ixz="287.62"
        iyy="16993"
        iyz="-523.85"
        izz="26995" />
    </inertial>
    <visual>
      <origin
        xyz="0 0 0"
        rpy="0 0 0" />
      <geometry>
        <mesh
          filename="package://robotic_arm/meshes/link_3.STL" />
      </geometry>
      <material
        name="">
        <color
          rgba="0.79216 0.81961 0.93333 1" />
      </material>
    </visual>
    <collision>
      <origin
        xyz="0 0 0"
        rpy="0 0 0" />
      <geometry>
        <mesh
          filename="package://robotic_arm/meshes/link_3.STL" />
      </geometry>
    </collision>
  </link>
  <joint
    name="joint_3"
    type="continuous">
    <origin
      xyz="-0.024 -0.195 -0.019"
      rpy="3.1416 0 0" />
    <parent
      link="link_2" />
    <child
      link="link_3" />
    <axis
      xyz="0 0 1" />
    <limit
      lower="0"
      upper="0"
      effort="0"
      velocity="0" />
  </joint>
  <link
    name="link_4">
    <inertial>
      <origin
        xyz="-0.00050964 -0.011144 0.1062"
        rpy="0 0 0" />
      <mass
        value="0.10507" />
      <inertia
        ixx="1573100000"
        ixy="195670000"
        ixz="40"
        iyy="51205000"
        iyz="1350"
        izz="1589800000" />
    </inertial>
    <visual>
      <origin
        xyz="0 0 0"
        rpy="0 0 0" />
      <geometry>
        <mesh
          filename="package://robotic_arm/meshes/link_4.STL" />
      </geometry>
      <material
        name="">
        <color
          rgba="0.69804 0.69804 0.69804 1" />
      </material>
    </visual>
    <collision>
      <origin
        xyz="0 0 0"
        rpy="0 0 0" />
      <geometry>
        <mesh
          filename="package://robotic_arm/meshes/link_4.STL" />
      </geometry>
    </collision>
  </link>
  <joint
    name="joint_4"
    type="continuous">
    <origin
      xyz="0.019 0.024 0"
      rpy="3.1416 1.5656 3.1345" />
    <parent
      link="link_3" />
    <child
      link="link_4" />
    <axis
      xyz="0 0 1" />
    <limit
      lower="0"
      upper="0"
      effort="0"
      velocity="0" />
  </joint>
  <link
    name="link_5">
    <inertial>
      <origin
        xyz="0.00054632 0.012004 -0.00063149"
        rpy="0 0 0" />
      <mass
        value="0.05168" />
      <inertia
        ixx="26860"
        ixy="525.09"
        ixz="287.62"
        iyy="16993"
        iyz="-523.85"
        izz="26995" />
    </inertial>
    <visual>
      <origin
        xyz="0 0 0"
        rpy="0 0 0" />
      <geometry>
        <mesh
          filename="package://robotic_arm/meshes/link_5.STL" />
      </geometry>
      <material
        name="">
        <color
          rgba="0.79216 0.81961 0.93333 1" />
      </material>
    </visual>
    <collision>
      <origin
        xyz="0 0 0"
        rpy="0 0 0" />
      <geometry>
        <mesh
          filename="package://robotic_arm/meshes/link_5.STL" />
      </geometry>
    </collision>
  </link>
  <joint
    name="joint_5"
    type="continuous">
    <origin
      xyz="-0.00099824 -0.022521 0.20866"
      rpy="-3.1379 -1.5656 3.1416" />
    <parent
      link="link_4" />
    <child
      link="link_5" />
    <axis
      xyz="0 0 1" />
    <limit
      lower="0"
      upper="0"
      effort="0"
      velocity="0" />
  </joint>
  <link
    name="link_6">
    <inertial>
      <origin
        xyz="9.9252E-09 -4.0368E-07 0.018675"
        rpy="0 0 0" />
      <mass
        value="0.006005" />
      <inertia
        ixx="3316900"
        ixy="-10"
        ixz="0"
        iyy="3315500"
        iyz="0"
        izz="185540" />
    </inertial>
    <visual>
      <origin
        xyz="0 0 0"
        rpy="0 0 0" />
      <geometry>
        <mesh
          filename="package://robotic_arm/meshes/link_6.STL" />
      </geometry>
      <material
        name="">
        <color
          rgba="0.69804 0.69804 0.69804 1" />
      </material>
    </visual>
    <collision>
      <origin
        xyz="0 0 0"
        rpy="0 0 0" />
      <geometry>
        <mesh
          filename="package://robotic_arm/meshes/link_6.STL" />
      </geometry>
    </collision>
  </link>
  <joint
    name="joint_6"
    type="continuous">
    <origin
      xyz="0.01883 0.02412 0"
      rpy="-1.5708 1.5312 -1.5637" />
    <parent
      link="link_5" />
    <child
      link="link_6" />
    <axis
      xyz="0 0 1" />
    <limit
      lower="0"
      upper="0"
      effort="0"
      velocity="0" />
  </joint>
  
  <transmission name="link_1_trans">
		<type>transmission_interface/SimpleTransmission</type>
		<joint name="joint_1">
			<hardwareInterface>hardware_interface/PositionJointInterface</hardwareInterface>
		</joint>
		<actuator name="link_1_motor">
			<hardwareInterface>hardware_interface/PositionJointInterface</hardwareInterface>
			<mechanicalReduction>1</mechanicalReduction>
		</actuator>
	</transmission>

	<transmission name="link_2_trans">
		<type>transmission_interface/SimpleTransmission</type>
		<joint name="joint_2">
			<hardwareInterface>hardware_interface/PositionJointInterface</hardwareInterface>
		</joint>
		<actuator name="link_2_motor">
			<hardwareInterface>hardware_interface/PositionJointInterface</hardwareInterface>
			<mechanicalReduction>1</mechanicalReduction>
		</actuator>
	</transmission>

	<transmission name="link_3_trans">
		<type>transmission_interface/SimpleTransmission</type>
		<joint name="joint_3">
			<hardwareInterface>hardware_interface/PositionJointInterface</hardwareInterface>
		</joint>
		<actuator name="link_3_motor">
			<hardwareInterface>hardware_interface/PositionJointInterface</hardwareInterface>
			<mechanicalReduction>1</mechanicalReduction>
		</actuator>
	</transmission>

	<transmission name="link_4_trans">
		<type>transmission_interface/SimpleTransmission</type>
		<joint name="joint_4">
			<hardwareInterface>hardware_interface/PositionJointInterface</hardwareInterface>
		</joint>
		<actuator name="link_4_motor">
			<hardwareInterface>hardware_interface/PositionJointInterface</hardwareInterface>
			<mechanicalReduction>1</mechanicalReduction>
		</actuator>
	</transmission>

	<transmission name="link_5_trans">
		<type>transmission_interface/SimpleTransmission</type>
		<joint name="joint_5">
			<hardwareInterface>hardware_interface/PositionJointInterface</hardwareInterface>
		</joint>
		<actuator name="link_5_motor">
			<hardwareInterface>hardware_interface/PositionJointInterface</hardwareInterface>
			<mechanicalReduction>1</mechanicalReduction>
		</actuator>
	</transmission>

	<transmission name="link_6_trans">
		<type>transmission_interface/SimpleTransmission</type>
		<joint name="joint_6">
			<hardwareInterface>hardware_interface/PositionJointInterface</hardwareInterface>
		</joint>
		<actuator name="link_6_motor">
			<hardwareInterface>hardware_interface/PositionJointInterface</hardwareInterface>
			<mechanicalReduction>1</mechanicalReduction>
		</actuator>
	</transmission>

	<gazebo>
		<plugin name="control" filename="libgazebo_ros_control.so">
			<robotNamespace>/</robotNamespace>
		</plugin>
	</gazebo>

	<gazebo reference="link_1">
		<selfCollide>true</selfCollide>
	</gazebo>

	<gazebo reference="link_2">
		<selfCollide>true</selfCollide>
	</gazebo>

	<gazebo reference="link_3">
		<selfCollide>true</selfCollide>
	</gazebo>

	<gazebo reference="link_4">
		<selfCollide>true</selfCollide>
	</gazebo>

	<gazebo reference="link_5">
		<selfCollide>true</selfCollide>
	</gazebo>

	<gazebo reference="link_6">
		<selfCollide>true</selfCollide>
	</gazebo>


</robot>